<mujoco model="robotiq_hande">
    <compiler angle="radian" meshdir="hande/assets/stl/" />
    <size njmax="500" nconmax="100" />
    <asset>
        <mesh name="hand-e" file="hand-e.stl" />
        <mesh name="finger_1" file="finger_1.stl" />
        <mesh name="finger_2" file="finger_2.stl" />
    </asset>
    <worldbody>
        <geom type="mesh" contype="0" conaffinity="0" group="1" rgba="0.1 0.1 0.1 1" mesh="hand-e" />
        <geom type="mesh" rgba="0.1 0.1 0.1 1" mesh="hand-e" />
        <body name="hande_left_finger" pos="0 0 0.099">
            <inertial pos="0.02262 -0.00759 0.00738" quat="0.871952 0.0369732 -0.211073 0.440205" mass="0.03804" diaginertia="1.22763e-05 1.22763e-05 1.22763e-05" />
            <joint name="hande_left_finger_joint" pos="0 0 0" axis="-1 0 0" type="slide" limited="true" range="0 0.025" />
            <geom type="mesh" contype="0" conaffinity="0" group="1" rgba="0.4 0.4 0.4 1" mesh="finger_1" />
            <geom type="mesh" rgba="0.4 0.4 0.4 1" mesh="finger_1" />
        </body>
        <body name="hande_right_finger" pos="0 0 0.099">
            <inertial pos="-0.02262 0.00759 0.00738" quat="0.871952 -0.0369732 0.211073 0.440205" mass="0.03804" diaginertia="1.22763e-05 1.22763e-05 1.22763e-05" />
            <joint name="hande_right_finger_joint" pos="0 0 0" axis="1 0 0" type="slide" limited="true" range="0 0.025" />
            <geom type="mesh" contype="0" conaffinity="0" group="1" rgba="0.4 0.4 0.4 1" mesh="finger_2" />
            <geom type="mesh" rgba="0.4 0.4 0.4 1" mesh="finger_2" />
        </body>
    </worldbody>
</mujoco>
