<mujoco model="ur5e">
  <compiler angle="radian" meshdir="assets" autolimits="true"/>
  <option integrator="Euler" timestep="0.01" iterations="10" tolerance="1e-10" impratio="20"/>

  <default>
    <default class="ur5e">
      <material specular="0.5" shininess="0.25"/>
      <joint axis="0 1 0" range="-6.28319 6.28319" armature="0.1" damping='100'/>
      <default class="GRIPPER">
        <joint damping='5'/>
      </default>

      <default class="visual">
        <geom type="mesh" contype="0" conaffinity="0" group="2"/>
      </default>
      <default class="collision">
        <geom type="capsule" group="3"/>
        <default class="eef_collision">
          <geom type="cylinder"/>
        </default>
      </default>
      <site size="0.001" rgba="0.5 0.5 0.5 0.3" group="4"/>
    </default>
  </default>

  <asset>
    <material class="ur5e" name="black" rgba="0.033 0.033 0.033 1"/>
    <material class="ur5e" name="jointgray" rgba="0.278 0.278 0.278 1"/>
    <material class="ur5e" name="linkgray" rgba="0.82 0.82 0.82 1"/>
    <material class="ur5e" name="urblue" rgba="0.49 0.678 0.8 1"/>

    <mesh file="base_0.obj"/>
    <mesh file="base_1.obj"/>
    <mesh file="shoulder_0.obj"/>
    <mesh file="shoulder_1.obj"/>
    <mesh file="shoulder_2.obj"/>
    <mesh file="upperarm_0.obj"/>
    <mesh file="upperarm_1.obj"/>
    <mesh file="upperarm_2.obj"/>
    <mesh file="upperarm_3.obj"/>
    <mesh file="forearm_0.obj"/>
    <mesh file="forearm_1.obj"/>
    <mesh file="forearm_2.obj"/>
    <mesh file="forearm_3.obj"/>
    <mesh file="wrist1_0.obj"/>
    <mesh file="wrist1_1.obj"/>
    <mesh file="wrist1_2.obj"/>
    <mesh file="wrist2_0.obj"/>
    <mesh file="wrist2_1.obj"/>
    <mesh file="wrist2_2.obj"/>
    <mesh file="wrist3.obj"/>

    <mesh name="robotiq_85_base_link_coarse" file="robotiq_85_base_link_coarse.STL" />
    <mesh name="inner_knuckle_coarse" file="inner_knuckle_coarse.STL" />
    <mesh name="inner_finger_coarse" file="inner_finger_coarse.STL" />
    <mesh name="outer_knuckle_coarse" file="outer_knuckle_coarse.STL" />
    <mesh name="outer_finger_coarse" file="outer_finger_coarse.STL" />
  </asset>

  <worldbody>
    <light name="spotlight" mode="targetbodycom" target="wrist_2_link" pos="0 -1 2"/>
    <!--body name="base" pos="0 0 0.74" quat=" 1 0 0 0" childclass="ur5e"-->
    <body name="base" pos="0 0 0" quat=" 0 0 0 1" childclass="ur5e">
      <inertial mass="4.0" pos="0 0 0" diaginertia="0.00443333156 0.00443333156 0.0072"/>
      <geom mesh="base_0" material="black" class="visual"/>
      <geom mesh="base_1" material="jointgray" class="visual"/>
      <body name="shoulder_link" pos="0 0 0.163">
        <inertial mass="3.7" pos="0 0 0" diaginertia="0.0102675 0.0102675 0.00666"/>
        <joint name="joint1" class="ur5e" axis="0 0 1" limited="true" range="-3.14159 3.14159"/>
        <geom mesh="shoulder_0" material="urblue" class="visual"/>
        <geom mesh="shoulder_1" material="black" class="visual"/>
        <geom mesh="shoulder_2" material="jointgray" class="visual"/>
        <geom class="collision" size="0.06 0.06" pos="0 0 -0.04"/>
        <body name="upper_arm_link" pos="0 0.138 0" quat="1 0 1 0">
          <inertial mass="8.393" pos="0 0 0.2125" diaginertia="0.133886 0.133886 0.0151074"/>
          <joint name="joint2" class="ur5e" limited="true" range="-3.14159 3.14159"/>
          <geom mesh="upperarm_0" material="linkgray" class="visual"/>
          <geom mesh="upperarm_1" material="black" class="visual"/>
          <geom mesh="upperarm_2" material="jointgray" class="visual"/>
          <geom mesh="upperarm_3" material="urblue" class="visual"/>
          <geom class="collision" pos="0 -0.04 0" quat="1 1 0 0" size="0.06 0.06"/>
          <geom class="collision" size="0.05 0.2" pos="0 0 0.2"/>
          <body name="forearm_link" pos="0 -0.131 0.425">
            <inertial mass="2.275" pos="0 0 0.196" diaginertia="0.0311796 0.0311796 0.004095"/>
            <joint name="joint3" class="ur5e" limited="true" range="-3.14159 3.14159" />
            <geom mesh="forearm_0" material="urblue" class="visual"/>
            <geom mesh="forearm_1" material="linkgray" class="visual"/>
            <geom mesh="forearm_2" material="black" class="visual"/>
            <geom mesh="forearm_3" material="jointgray" class="visual"/>
            <geom class="collision" pos="0 0.08 0" quat="1 1 0 0" size="0.055 0.06"/>
            <geom class="collision" size="0.038 0.19" pos="0 0 0.2"/>
            <body name="wrist_1_link" pos="0 0 0.392" quat="1 0 1 0">
              <inertial mass="1.219" pos="0 0.127 0" diaginertia="0.0025599 0.0025599 0.0021942"/>
              <joint name="joint4" class="ur5e" limited="true" range="-3.14159 3.14159" />
              <geom mesh="wrist1_0" material="black" class="visual"/>
              <geom mesh="wrist1_1" material="urblue" class="visual"/>
              <geom mesh="wrist1_2" material="jointgray" class="visual"/>
              <geom class="collision" pos="0 0.05 0" quat="1 1 0 0" size="0.04 0.07"/>
              <body name="wrist_2_link" pos="0 0.127 0">
                <inertial mass="1.219" pos="0 0 0.1" diaginertia="0.0025599 0.0025599 0.0021942"/>
                <joint name="joint5" axis="0 0 1" class="ur5e" limited="true" range="-3.14159 3.14159" />
                <geom mesh="wrist2_0" material="black" class="visual"/>
                <geom mesh="wrist2_1" material="urblue" class="visual"/>
                <geom mesh="wrist2_2" material="jointgray" class="visual"/>
                <geom class="collision" size="0.04 0.06" pos="0 0 0.04"/>
                <geom class="collision" pos="0 0.02 0.1" quat="1 1 0 0" size="0.04 0.04"/>
                <body name="wrist_3_link" pos="0 0 0.1">
                  <inertial mass="0.1889" pos="0 0.0771683 0" quat="1 0 0 1"
                    diaginertia="0.000132134 9.90863e-05 9.90863e-05"/>
                  <joint name="joint6" class="ur5e" limited="true" range="-3.14159 3.14159" />
                  <geom material="linkgray" mesh="wrist3" class="visual"/>
                  <geom class="eef_collision" pos="0 0.08 0" quat="1 1 0 0" size="0.04 0.02"/>
                  <!--site name="attachment_site" pos="0 0.1 0" quat="-1 1 0 0"/>
                  <site name="UR/EE" pos="0 0 0" quat="0 1 0 1" type="sphere" rgba="135 211 124 1" size="1"/-->
                  
                  <body name="ee_link" pos="0 0.0823 0" quat="0.707107 0 0 0.707107">
                    <inertial pos="-0.01 0 0" mass="0.001" diaginertia="1.66667e-08 1.66667e-08 1.66667e-08" />
                    <geom size="0.005 0.005 0.005" pos="-0.01 0 0" type="box" />
                    <!--GRIPPER-->
                      <!-- <joint name="ee_to_base" pos="0 0 0" axis="1 0 0" limited="true" range="0 0" /> -->
                        <body name="robotiq_85_base_link" pos="0 0 0" quat="0.5 0.5 0.5 0.5 ">
                         <inertial pos="0.00021987 -2.3546e-10 0.030163"  quat="0 1 0 1" mass="0.30915" diaginertia="0.00030737 0.000289758 0.000199102" />
                          <geom type="mesh" rgba="0.1 0.1 0.1 1" friction="0.8 0.8 0.8" mesh="robotiq_85_base_link_coarse" />
                          <body name="left_inner_knuckle" pos="0.0127 0 0.0693075">
                            <inertial pos="0.0170975 -3.93809e-10 0.0224918"   quat="0.947655 0 -0.319297 0" mass="0.0110931" diaginertia="5.59353e-06 3.96549e-06 1.88108e-06" />
                            <geom type="mesh" rgba="0.1 0.1 0.1 1" friction="0.8 0.8 0.8" mesh="inner_knuckle_coarse" />
                            <joint name="base_to_lik" class="GRIPPER" pos="0 0 0" axis="0 1 0" limited="true" range="-1 1" />

                            <body name="left_inner_finger" pos="0.0345853 0 0.045497" >
                            <inertial pos="0.00602756 0 0.00669926"  quat="0.699065 0.106339 0.106339 0.699065" mass="0.00724255" diaginertia="1.70064e-06 1.58577e-06 3.69621e-07" />
                            <geom type="mesh" rgba="0.1 0.1 0.1 1" friction="0.8 0.8 0.8" mesh="inner_finger_coarse" />
                            </body>
                          </body>

                          <body name="right_inner_knuckle" pos="-0.0127 0 0.0693075" quat="0 0 0 1">
                            <inertial pos="0.0168606 3.93808e-10 0.02267"  quat="0.949317 0 -0.314322 0" mass="0.0110931" diaginertia="5.59353e-06 3.96549e-06 1.88108e-06" />
                            <geom type="mesh" rgba="0.1 0.1 0.1 1" friction="0.8 0.8 0.8" mesh="inner_knuckle_coarse" />
                            <joint name="base_to_rik" class="GRIPPER" pos="0 0 0" axis="0 1 0" limited="true" range="-1 1" />

                            <body name="right_inner_finger" pos="0.034106 0 0.0458574">
                              <inertial pos="0.00602756 0 0.00669926"  quat="0.699065 0.106339 0.106339 0.699065" mass="0.00724255" diaginertia="1.70064e-06 1.58577e-06 3.69621e-07" />
                              <geom type="mesh" rgba="0.1 0.1 0.1 1" friction="0.8 0.8 0.8" mesh="inner_finger_coarse" />
                            </body>
                          </body>
                        </body>
                    </body>
                </body>
              </body>
            </body>
          </body>
        </body>
      </body>
    </body>
  </worldbody>

  <equality>
		<joint name="fingers" joint1="base_to_rik" joint2="base_to_lik" polycoef="0 1 0 0 0"/>
	</equality>

  <actuator>
    <position name='actuator1' ctrllimited="true" ctrlrange="-3.14159 3.14159" joint="joint1" kp="1000"/>
    <position name='actuator2' ctrllimited="true" ctrlrange="-3.14159 3.14159" joint="joint2" kp="1000"/>
    <position name='actuator3' ctrllimited="true" ctrlrange="-3.14159 3.14159" joint="joint3" kp="1000"/>
    <position name='actuator4' ctrllimited="true" ctrlrange="-3.14159 3.14159" joint="joint4" kp="1000"/>
    <position name='actuator5' ctrllimited="true" ctrlrange="-3.14159 3.14159" joint="joint5" kp="1000"/>
    <position name='actuator6' ctrllimited="true" ctrlrange="-3.14159 3.14159" joint="joint6" kp="1000"/>

    <motor name='actuator7' ctrllimited="true" ctrlrange="-1 1" joint='base_to_lik' gear="101"/>
  </actuator>

  <!--sensor>
		
		<framepos name="UR/EE_pos" objtype="site" objname="UR/EE" />
		<framequat name="UR/EE_quat" objtype="site" objname="UR/EE" />
		
		<force name="TcpF" site="UR/EE" />
		<torque name="TcpT" site="UR/EE"/>
  </sensor-->

  <!--keyframe>
    <key name="home" qpos="-1.5708 -1.5708 1.5708 -1.5708 -1.5708 0" ctrl="-1.5708 -1.5708 1.5708 -1.5708 -1.5708 0"/>
  </keyframe-->
</mujoco>
